<!DOCTYPE html>
<html lang="en">

<head>
  <meta charset="UTF-8">
  <meta name="viewport" content="width=device-width, initial-scale=1.0">
  <title>JS</title>
</head>

<body>
  <h1>Handle onRejected using async/await</h1>
  <p>
    Perlu jadi catatan bahwa await hanya akan mengembalikan nilai jika promise berhasil dilakukan (onFulfilled). Lantas
    bagaimana jika promise gagal dilakukan (onRejected)? Kembali lagi kepada prinsip synchronous code. Kita dapat
    menangani sebuah eror atau tolakan dengan menggunakan try...catch.

    Ketika menggunakan async/await, biasakan ketika mendapatkan resolved value dari sebuah promise, untuk menempatkannya
    di dalam block try seperti ini:
  </p>
  <code>
    <pre>
      async function makeCoffee() {
        try {
          const coffee = await getCoffee();
          console.log(coffee);
        }
       }
    </pre>
  </code>
  <p>
    Dengan begitu kita dapat menggunakan block catch untuk menangani jika promise gagal dilakukan (onRejected).
  </p>
  <code>
    <pre>
      async function makeCoffee() {
        try {
          const coffee = await getCoffee();
        console.log(coffee);
        } catch(rejectedReason) {
          console.log(rejectedReason);
        }
       }
        
       makeCoffee();
        
       /* output
       Biji kopi habis!
       */       
    </pre>
  </code>
  <script>

  </script>
</body>

</html>